<?xml version="1.0" ?>
<sdf version="1.8">
  <model name="car">
    <pose>0 0 0.5 0 0 0</pose>

    <link name="base_link">
      <inertial>
        <mass>1.0</mass>
        <inertia>
          <ixx>0.1</ixx><ixy>0</ixy><ixz>0</ixz>
          <iyy>0.1</iyy><iyz>0</iyz><izz>0.1</izz>
        </inertia>
      </inertial>
      <visual name="visual">
        <geometry><box><size>0.4 0.2 0.1</size></box></geometry>
        <material><ambient>0 0 1 1</ambient><diffuse>0 0 1 1</diffuse></material>
      </visual>
      <collision name="collision">
        <geometry><box><size>0.4 0.2 0.1</size></box></geometry>
      </collision>

      <!-- Caméra pointée vers le sol -->
      <sensor name="camera" type="camera">
        <pose>0.2 0 0.1 0 0.7854 0</pose>
        <update_rate>30</update_rate>
        <camera>
          <horizontal_fov>1.047</horizontal_fov>
          <image>
            <width>320</width>
            <height>240</height>
            <format>R8G8B8</format>
          </image>
          <clip><near>0.02</near><far>10</far></clip>
        </camera>
        <plugin filename="gz-sim-sensors-system" name="gz::sim::systems::Sensors"/>
        <topic>camera/image_raw</topic>
        <always_on>1</always_on>
        <visualize>true</visualize>
      </sensor>
    </link>

    <link name="left_wheel">
      <pose>0 0.15 -0.3 1.5707 0 0</pose>
      <inertial>
        <mass>0.1</mass>
        <inertia>
          <ixx>0.001</ixx><ixy>0</ixy><ixz>0</ixz>
          <iyy>0.001</iyy><iyz>0</iyz><izz>0.001</izz>
        </inertia>
      </inertial>
      <visual name="visual">
        <geometry><cylinder><radius>0.1</radius><length>0.05</length></cylinder></geometry>
        <material><ambient>0 0 0 1</ambient><diffuse>0 0 0 1</diffuse></material>
      </visual>
      <collision name="collision">
        <geometry><cylinder><radius>0.1</radius><length>0.05</length></cylinder></geometry>
        <surface><friction><ode><mu>1.0</mu><mu2>1.0</mu2></ode></friction></surface>
      </collision>
    </link>

    <link name="right_wheel">
      <pose>0 -0.15 -0.3 1.5707 0 0</pose>
      <inertial>
        <mass>0.1</mass>
        <inertia>
          <ixx>0.001</ixx><ixy>0</ixy><ixz>0</ixz>
          <iyy>0.001</iyy><iyz>0</iyz><izz>0.001</izz>
        </inertia>
      </inertial>
      <visual name="visual">
        <geometry><cylinder><radius>0.1</radius><length>0.05</length></cylinder></geometry>
        <material><ambient>0 0 0 1</ambient><diffuse>0 0 0 1</diffuse></material>
      </visual>
      <collision name="collision">
        <geometry><cylinder><radius>0.1</radius><length>0.05</length></cylinder></geometry>
        <surface><friction><ode><mu>1.0</mu><mu2>1.0</mu2></ode></friction></surface>
      </collision>
    </link>

    <link name="caster">
      <pose>-0.15 0 -0.35 0 0 0</pose>
      <inertial>
        <mass>0.05</mass>
        <inertia>
          <ixx>0.0001</ixx><ixy>0</ixy><ixz>0</ixz>
          <iyy>0.0001</iyy><iyz>0</iyz><izz>0.0001</izz>
        </inertia>
      </inertial>
      <visual name="visual">
        <geometry><sphere><radius>0.05</radius></sphere></geometry>
        <material><ambient>0.5 0.5 0.5 1</ambient></material>
      </visual>
      <collision name="collision">
        <geometry><sphere><radius>0.05</radius></sphere></geometry>
        <surface><friction><ode><mu>0.0</mu><mu2>0.0</mu2></ode></friction></surface>
      </collision>
    </link>

    <joint name="left_wheel_joint" type="revolute">
      <parent>base_link</parent>
      <child>left_wheel</child>
      <axis>
        <xyz>0 0 1</xyz>
        <limit><lower>-1e16</lower><upper>1e16</upper></limit>
      </axis>
    </joint>

    <joint name="right_wheel_joint" type="revolute">
      <parent>base_link</parent>
      <child>right_wheel</child>
      <axis>
        <xyz>0 0 1</xyz>
        <limit><lower>-1e16</lower><upper>1e16</upper></limit>
      </axis>
    </joint>

    <joint name="caster_joint" type="ball">
      <parent>base_link</parent>
      <child>caster</child>
    </joint>

    <plugin filename="gz-sim-diff-drive-system" name="gz::sim::systems::DiffDrive">
      <left_joint>left_wheel_joint</left_joint>
      <right_joint>right_wheel_joint</right_joint>
      <wheel_separation>0.3</wheel_separation>
      <wheel_radius>0.1</wheel_radius>
      <topic>/model/car/cmd_vel</topic>
    </plugin>

  </model>
</sdf>