<?xml version="1.0"?>
<robot name="ackermann_car">

  <link name="base_footprint"/>

  <joint name="base_joint" type="fixed">
    <parent link="base_footprint"/>
    <child link="base_link"/>
    <origin xyz="0 0 0.05" rpy="0 0 0"/>
  </joint>

  <link name="base_link">
    <visual>
      <geometry><box size="0.4 0.2 0.1"/></geometry>
      <material name="blue"><color rgba="0 0 1 1"/></material>
    </visual>
    <collision>
      <geometry><box size="0.4 0.2 0.1"/></geometry>
    </collision>
    <inertial>
      <mass value="1.0"/>
      <inertia ixx="0.01" ixy="0" ixz="0" iyy="0.01" iyz="0" izz="0.01"/>
    </inertial>
  </link>

  <!-- Roue gauche -->
  <link name="left_wheel">
    <visual>
      <geometry><cylinder radius="0.04" length="0.04"/></geometry>
      <material name="black"><color rgba="0 0 0 1"/></material>
    </visual>
    <collision>
      <geometry><cylinder radius="0.04" length="0.04"/></geometry>
    </collision>
    <inertial>
      <mass value="0.1"/>
      <inertia ixx="0.001" ixy="0" ixz="0" iyy="0.001" iyz="0" izz="0.001"/>
    </inertial>
  </link>

  <joint name="left_wheel_joint" type="continuous">
    <parent link="base_link"/>
    <child link="left_wheel"/>
    <origin xyz="0 0.12 -0.05" rpy="1.5707 0 0"/>
    <axis xyz="0 0 1"/>
  </joint>

  <!-- Roue droite -->
  <link name="right_wheel">
    <visual>
      <geometry><cylinder radius="0.04" length="0.04"/></geometry>
      <material name="black"><color rgba="0 0 0 1"/></material>
    </visual>
    <collision>
      <geometry><cylinder radius="0.04" length="0.04"/></geometry>
    </collision>
    <inertial>
      <mass value="0.1"/>
      <inertia ixx="0.001" ixy="0" ixz="0" iyy="0.001" iyz="0" izz="0.001"/>
    </inertial>
  </link>

  <joint name="right_wheel_joint" type="continuous">
    <parent link="base_link"/>
    <child link="right_wheel"/>
    <origin xyz="0 -0.12 -0.05" rpy="1.5707 0 0"/>
    <axis xyz="0 0 1"/>
  </joint>

  <!-- Caméra -->
  <link name="camera_link">
    <visual>
      <geometry><box size="0.05 0.05 0.05"/></geometry>
      <material name="red"><color rgba="1 0 0 1"/></material>
    </visual>
  </link>

  <joint name="camera_joint" type="fixed">
    <parent link="base_link"/>
    <child link="camera_link"/>
    <origin xyz="0.2 0 0.08" rpy="0 0.5 0"/>
  </joint>

  <!-- Plugins Gazebo -->
  <gazebo>
    <plugin filename="gz-sim-diff-drive-system" name="gz::sim::systems::DiffDrive">
      <left_joint>left_wheel_joint</left_joint>
      <right_joint>right_wheel_joint</right_joint>
      <wheel_separation>0.24</wheel_separation>
      <wheel_radius>0.04</wheel_radius>
      <topic>cmd_vel</topic>
      <odom_topic>odom</odom_topic>
      <frame_id>odom</frame_id>
      <child_frame_id>base_footprint</child_frame_id>
    </plugin>
  </gazebo>

  <gazebo reference="camera_link">
    <sensor name="camera" type="camera">
      <update_rate>30</update_rate>
      <camera>
        <horizontal_fov>1.3962634</horizontal_fov>
        <image>
          <width>320</width>
          <height>240</height>
          <format>R8G8B8</format>
        </image>
        <clip><near>0.02</near><far>300</far></clip>
      </camera>
      <plugin filename="gz-sim-camera-sensor-system" name="gz::sim::systems::CameraSensor"/>
      <topic>camera/image_raw</topic>
    </sensor>
  </gazebo>

</robot>
